Workbook
Name ASD: #REF!
Name ASD: #REF!
Name ASD: #REF!
Name ASD: #REF!
Name asdfsdf: #REF!
Name asdfsdf: #REF!
Name asdfsdf: #REF!
Name asdfsdf: #REF!
Name asdfsdf: #REF!
Name asdfsdf: #REF!
Name asdfsdf: #REF!
Name sdfsdf: #REF!
Name sdfsdf: #REF!
Name sdfsdf: #REF!
Name sdfsdf: #REF!
Name sdfsdf: #REF!
Name sdfsdf: #REF!
Name sdfsdf: #REF!

Sheet Annexure-I
A1: SL NO | B1: INDENT PART NO | C1: DESCRIPTION | D1: INDENT QTY | E1: Revised INDENT QTY | F1: Ref Unit Basic Price (USD) | G1: REF SA | H1: Ref. SA DATE | I1: Price Level | J1: EST Unit Price (USD) @ 2024 level | K1: Levelled EST Unit Price (Rs) @ 2024 level | L1: LLP REF SA Price | M1: LLP REF SA | N1: LLP REF SA Date | O1: Price Level | P1: LLP EST Unit Price (USD) @ 2024 level | Q1: Levelled LPP Unit Price (Rs) @ 2024 level | R1: Currency
A2: 1 | B2: X1 | C2: OPERATIONAL AMPLIFIER | D2: 7 | E2: 7 | F2: 11 | G2: CONTRACT-A1 | H2: 43298 | I2: 2018 | J2: 14.83 | K2: 1623.4145 | R2: USD
A3: 2 | B3: X2 | C3: MICROCIRCUIT OF KOPYO RADAR | D3: 38 | E3: 38 | F3: 16.16 | G3: CONTRACT-A2 | H3: 40967 | I3: 2012 | J3: 29.61 | K3: 3241.3555 | R3: USD
A4: 3 | B4: X3 | C4: IC (Integrated Circuit ) | D4: 12 | E4: 12 | F4: 22 | G4: CONTRACT-A3 | H4: 43298 | I4: 2018 | J4: 29.65 | K4: 3245.7343 | R4: USD
A5: 4 | B5: X4 | C5: MICROCIRCUIT | D5: 10 | E5: 10 | F5: 7.93 | G5: CONTRACT-A4 | H5: 40967 | I5: 2012 | J5: 14.53 | K5: 1590.574 | R5: USD
A6: 5 | B6: X5 | C6: IC (Integrated Circuit ) | D6: 9 | E6: 9 | F6: 14 | G6: CONTRACT-A5 | H6: 43298 | I6: 2018 | J6: 18.87 | K6: 2065.6663 | R6: USD
A7: 6 | B7: X6 | C7: DIODE | D7: 11 | E7: 11 | F7: 12.02 | G7: CONTRACT-A6 | H7: 41789 | I7: 2014 | J7: 19.79 | K7: 2166.3771 | R7: USD
A8: 7 | B8: X7 | C8: TRANSISTOR | D8: 6 | E8: 6 | F8: 280 | G8: CONTRACT-A7 | H8: 44760 | I8: 2022 | J8: 309.29 | K8: 364.9622 | R8: INR
A9: 8 | B9: X8 | C9: TRANSISTOR | D9: 16 | E9: 16 | F9: 57.75 | G9: CONTRACT-A8 | H9: 40724 | I9: 2011 | J9: 111.94 | K9: 12253.878 | R9: USD
A10: 9 | B10: X9 | C10: TRANSISTOR | D10: 17 | E10: 17 | F10: 6 | G10: CONTRACT-A9 | H10: 43298 | I10: 2018 | J10: 8.09 | K10: 885.59832 | R10: USD
A11: 10 | B11: X10 | C11: IC (Integrated Circuit ) | D11: 30 | E11: 30 | F11: 18.81 | G11: CONTRACT-A10 | H11: 41891 | I11: 2014 | J11: 30.96 | K11: 3389.1377 | R11: USD
A12: 11 | B12: X11 | C12: MOSFET | D12: 4 | E12: 4 | F12: 46 | G12: CONTRACT-A11 | H12: 43298 | I12: 2018 | J12: 62 | K12: 6787.0329 | R12: USD
A13: 12 | B13: X12 | C13: IC (Integrated Circuit ) | D13: 12 | E13: 12 | F13: 12 | G13: CONTRACT-A12 | H13: 43298 | I13: 2018 | J13: 16.17 | K13: 1770.102 | R13: USD
... A28: 27 | B28: X27 | C28: FUSE HOLDER | D28: 121 | E28: 121 | F28: 7.03 | G28: CONTRACT-A27 | H28: 41789 | I28: 2014 | J28: 11.57 | K28: 1266.5479 | R28: USD
A29: 28 | B29: X28 | C29: HIGH VOLTAGE SEALENT | D29: 15 | E29: 15 | F29: 29.97 | G29: CONTRACT-A28 | H29: 29-12-2015 | I29: 2015 | J29: 46.89 | K29: 5132.9673 | R29: USD
A30: 29 | B30: X29 | C30: ELECTRIC TIMER | D30: 3 | E30: 3 | F30: 822.53 | G30: CONTRACT-A29 | H30: 40967 | I30: 2012 | J30: 1506.94 | K30: 164962.12 | R30: USD
A31: 30 | B31: X30 | C31: UNIT 08-11 UFTI / FORMER | D31: 4 | E31: 4 | F31: 35494.03 | G31: CONTRACT-A30 | H31: 40967 | I31: 2012 | J31: 65027.94 | K31: 7118496.2 | R31: USD
A32: 31 | B32: X31 | C32: CAPACITOR | D32: 10 | E32: 10 | F32: 7.34 | G32: CONTRACT-A31 | H32: 40967 | I32: 2012 | J32: 13.45 | K32: 1472.3483 | R32: USD
A33: 32 | B33: X32 | C33: CAPACITOR | D33: 20 | E33: 20 | F33: 4.26 | G33: CONTRACT-A32 | H33: 40966 | I33: 2012 | J33: 7.8 | K33: 853.85252 | R33: USD
A34: 33 | B34: X33 | C34: CAPACITOR | D34: 110 | E34: 110 | F34: 6.65 | G34: CONTRACT-A33 | H34: 30-06-2017 | I34: 2017 | J34: 9.42 | K34: 1031.1911 | R34: USD
A35: 34 | B35: X34 | C35: CAPACITOR | D35: 131 | E35: 131 | F35: 12.63 | G35: CONTRACT-A34 | H35: 24-12-2018 | I35: 2018 | J35: 17.02 | K35: 1863.15 | R35: USD
A36: 35 | B36: X35 | C36: CAPACITOR | D36: 10 | E36: 10 | F36: 92.28 | G36: CONTRACT-A35 | H36: 29-12-2015 | I36: 2015 | J36: 144.39 | K36: 15806.124 | R36: USD
A37: 36 | B37: X36 | C37: CAPACITOR | D37: 28 | E37: 28 | F37: 74.91 | G37: CONTRACT-A36 | H37: 40967 | I37: 2012 | J37: 137.24 | K37: 15023.426 | R37: USD
A38: 37 | B38: X37 | C38: FRAME | D38: 5 | E38: 5 | F38: 9217.05 | G38: CONTRACT-A37 | H38: 40967 | I38: 2012 | J38: 16886.38 | K38: 1848522.8 | R38: USD
A39: 38 | B39: X38 | C39: CONTACTOR | D39: 12 | E39: 12 | F39: 1891.45 | G39: CONTRACT-A38 | H39: 40967 | I39: 2012 | J39: 3465.29 | K39: 379339.31 | R39: USD
A40: 39 | B40: X39 | C40: ARTICLE CONDOR-1 | D40: 4 | E40: 4 | F40: 96734.05 | G40: CONTRACT-A39 | H40: 41789 | I40: 2014 | J40: 159228.04 | K40: 17430418 | R40: USD
A41: 40 | B41: X40 | C41: TRUBKA PICTURE TUBE OF MFD | D41: 5 | E41: 5 | F41: 16818.44 | G41: CONTRACT-A40 | H41: 41789 | I41: 2014 | J41: 27683.81 | K41: 3030498.8 | R41: USD
A42: 41 | B42: X41 | C42: MICROSWITCH | D42: 20 | E42: 20 | F42: 80.29 | G42: CONTRACT-A41 | H42: 40967 | I42: 2012 | J42: 147.1 | K42: 16102.783 | R42: USD
A43: 42 | B43: X42 | C43: SWITCH | D43: 8 | E43: 8 | F43: 147.61 | G43: CONTRACT-A42 | H43: 40967 | I43: 2012 | J43: 270.43 | K43: 29603.505 | R43: USD
A44: 43 | B44: X43 | C44: SWITCH | D44: 8 | E44: 8 | F44: 240.88 | G44: CONTRACT-A43 | H44: 40967 | I44: 2012 | J44: 441.31 | K44: 48309.443 | R44: USD
A45: 44 | B45: X44 | C45: RELAY RS4.569.435-04.01 RS0.459.006 TU | D45: 5 | E45: 5 | F45: 217.1 | G45: CONTRACT-A44 | H45: 41789 | I45: 2014 | J45: 357.36 | K45: 39119.582 | R45: USD
A46: 45 | B46: X45 | C46: BACKELITE CONNECTOR | D46: 10 | E46: 10 | F46: 13.93 | G46: CONTRACT-A45 | H46: 29-12-2015 | I46: 2015 | J46: 21.8 | K46: 2386.4083 | R46: USD
A47: 46 | B47: X46 | C47: CABLE | D47: 10 | E47: 10 | F47: 179.59 | G47: CONTRACT-A46 | H47: 40967 | I47: 2012 | J47: 329.02 | K47: 36017.251 | R47: USD
A48: 47 | B48: X47 | C48: CABLE | D48: 9 | E48: 9 | F48: 179.59 | G48: CONTRACT-A47 | H48: 40967 | I48: 2012 | J48: 329.02 | K48: 36017.251 | R48: USD
A49: 48 | B49: X48 | C49: RESISTOR | D49: 14 | E49: 14 | F49: 3.91 | G49: CONTRACT-A48 | H49: 39386 | I49: 2007 | J49: 8.95 | K49: 979.74103 | R49: USD
A50: 49 | B50: X49 | C50: RESISTOR | D50: 22 | E50: 22 | F50: 0.41 | G50: CONTRACT-A49 | H50: 39386 | I50: 2007 | J50: 0.94 | K50: 102.90018 | R50: USD
A51: 50 | B51: X50 | C51: RESISTOR | D51: 31 | E51: 31 | F51: 1.75 | G51: CONTRACT-A50 | H51: 29-12-2015 | I51: 2015 | J51: 2.74 | K51: 299.94307 | R51: USD
A52: 51 | B52: X51 | C52: RESISTOR | D52: 5 | E52: 5 | F52: 20.26 | G52: CONTRACT-A51 | H52: 29-12-2015 | I52: 2015 | J52: 31.7 | K52: 3470.1442 | R52: USD
A53: 52 | B53: X52 | C53: UNIT PICTURE TUBE | D53: 3 | E53: 3 | F53: 19948 | G53: CONTRACT-A52 | H53: 41789 | I53: 2014 | J53: 32835.19 | K53: 3594411.5 | R53: USD
A54: 53 | B54: X53 | C54: PIN | D54: 5 | E54: 5 | F54: 414.87 | G54: CONTRACT-A53 | H54: 29-12-2015 | I54: 2015 | J54: 649.14 | K54: 71060.234 | R54: USD
...

Sheet Form
A1: Stage | B1: E No | C1: HEADING
A2: RFQ | C2: Indent NO | D2: abcd001 | E2: Price Recoverability | F2: Expenditure is fully recoverable in accordance with GOI, MOD letter No. Air HQ/95357/71/09-10/NSK/Fin P/AF/US(S)/D(Air-IV(I)/14 dated 12.09.2014, as applicable for BOI supplies against RMSO..
A3: RFQ | C3: Indent Date | D3: 45073
A4: RFQ | C4: File number | D4: 628
A5: RFQ | C5: Project | D5: MiG/SUROH | E5: Programme details (MFG/ROH/RMSO/ DRE/Others ): | H5: ROH
C6: Fleet | D6: MiG/SUROH | E6: Year provisioned
A7: RFQ | B7: E1 | C7: Type of File | D7: Procurement of BoI Spares & Repair of KOPYO Cards | E7: HAL/NK/MPU-AOD/xyz(208)/23/ dated 01.06.2023
A8: RFQ | C8: Tender Floated on Vendors | D8: 14
A9: RFQ | C9: Tender Opening date | D9: 19.07.2023 | E9: 11.08.2023
A10: TEC | C10: Conversion 1USD = INR | D10: 82.78 | E10: Price Level | F10: 2024
A11: TEC | C11: TEC Letter No
A12: TEC | C12: Reason for deletion of LInes | D12: TEC
C13: Note Sheet | D13: Date
C14: =CONCATENATE("HAL/NK/MPU-AOD/2237(",Form!D4,")/23/107/") -> HAL/NK/MPU-AOD/2237(628)/23/107/ | E14: Vendor | F14: Due Date Ext Letter | G14: Upto | H14: Approved upto
C15: N1 | D15: 44411
A16: DP1 | C16: N2 | D16: 44473
A17: DP2 | C17: N3
C18: N4
C19: N5
C20: N6
C21: N7
C22: N8
C23: N9
C24: N10
D25: ='CST-Calculation'!H3 -> Avi. Equip. | E25: ='CST-Calculation'!P3 -> GIS | F25: ='CST-Calculation'!T3 -> IASL | G25: ='CST-Calculation'!L3 -> Avitronic | H25: ='CST-Calculation'!X3 -> AEC | I25: ='CST-Calculation'!AB3 -> ADRYS | J25: ='CST-Calculation'!AF3 -> AZP | K25: ='CST-Calculation'!AJ3 -> EST | L25: ='CST-Calculation'!AN3 -> NASC | M25: ='CST-Calculation'!AR3 -> ROE | N25: ='CST-Calculation'!AV3 -> VEKS-M | O25: ='CST-Calculation'!AZ3 -> VSMPO | P25: ='CST-Calculation'!BD3 -> TDK
C26: =SUM(IF(D26<>"",1,0),IF(E26<>"",1,0),IF(F26<>"",1,0),IF(G26<>"",1,0),IF(H26<>"",1,0),IF(I26<>"",1,0),IF(J26<>"",1,0),IF(K26<>"",1,0),IF(L26<>"",1,0),IF(M26<>"",1,0),IF(N26<>"",1,0)) -> 4 | D26: =IF(SUM('CST-Calculation'!H5:H2129)>0,'CST-Calculation'!G2,"") | E26: =IF(SUM('CST-Calculation'!P5:P2129)>0,'CST-Calculation'!O2,"") -> GIS | F26: =IF(SUM('CST-Calculation'!T5:T2129)>0,'CST-Calculation'!S2,"") -> INDO AVIA SERVICES LTD | G26: =IF(SUM('CST-Calculation'!L5:L2129)>0,'CST-Calculation'!K2,"") | H26: =IF(SUM('CST-Calculation'!X5:X2129)>0,'CST-Calculation'!W2,"") | I26: =IF(SUM('CST-Calculation'!AB5:AB2129)>0,'CST-Calculation'!AA2,"") -> ADRYS Technologies (ADRYS) | J26: =IF(SUM('CST-Calculation'!AF5:AF2129)>0,'CST-Calculation'!AE2,"") | K26: =IF(SUM('CST-Calculation'!AJ5:AJ2129)>0,'CST-Calculation'!AI2,"") -> Eurasia Special Technologies (EST) | L26: =IF(SUM('CST-Calculation'!AN5:AN2129)>0,'CST-Calculation'!AM2,"") | M26: =IF(SUM('CST-Calculation'!AR5:AR2129)>0,'CST-Calculation'!AQ2,"") | N26: =IF(SUM('CST-Calculation'!AV5:AV2129)>0,'CST-Calculation'!AU2,"") | O26: =IF(SUM('CST-Calculation'!AW5:AW2129)>0,'CST-Calculation'!AV2,"") | P26: =IF(SUM('CST-Calculation'!AX5:AX2129)>0,'CST-Calculation'!AW2,"")
A27: CST | C27: Comm Offer Letter No. | D27: ASC/HAL/092/23 | E27: 94/08-356 In | F27: IASL/205(NK)/2023-24/0723001/095 | I27: ADTS/QUOTE/0720/HAL/IN-123001/23 | J27: 825/RM-27286 | K27: Email
A28: CST | C28: Comm Offer Date | D28: 45146 | E28: 45146 | F28: 45147 | I28: 45127 | J28: 45145 | K28: 10.08.2023
A29: CST | C29: Comm Offer Validity | D29: 90 days | E29: 45291 | F29: 60 days | I29: Offer is valid for 120 days from the closing date of enquiry. | J29: 45231 | K29: 180 days from Tender opening Date
A30: CST | C30: Delivery Schedule | D30: 12 months from the date of signing of contract. | E30: 12 months from the date of signing of contract. | F30: Within 16 months from the date of placement of order & EUC. | I30: 52-60 weeks from the date of receipt of PO. | J30: Within 09 months from the date of signing the contract. | K30: Within 365 days from the date of Purchase order
A31: CST | C31: Payment term | D31: 100% DBT in equivalent RUB. | E31: - | F31: 80% within 30 days of receipt. Remaining 20% after acceptance but within 45 days of receipt | I31: 100% payment within 30 days from the date of supply & acceptance. | J31: 100% DBT in equivalent RUB. | K31: 100% payment within 30 days of date of delivery
A32: TO | C32: Tender Due Extension request letter
A33: TO | C33: Tender Extension request letter upto
A34: PNC | C34: Non Deputation letter with date
A35: PNC | C35: Negotiation Date
A36: PP | C36: Purchase proposal No. (PP No)
A37: PP | C37: Draft Contract No
A38: PP | C38: Draft Contract Date
A39: PP | C39: Draft Contract Forwarding Letter No
A40: PP | C40: DC Forwarding Letter Date
...

Sheet CST-Calculation
A1: =CONCATENATE("Price Comparision Statement Against Indent ",Form!D2) -> Price Comparision Statement Against Indent abcd001
A2: RFQ DETAILS | G2: Aviation Equipment | K2: Avitronic Ltd, Russia | O2: GIS | S2: INDO AVIA SERVICES LTD | W2: AEC (AEC) | AA2: ADRYS Technologies (ADRYS) | AE2: AVIAZAPCHAST (AZP) | AI2: Eurasia Special Technologies (EST) | AM2: NASC (NASC) | AQ2: ROE (ROE) | AU2: VEKS-M | AY2: VSMPO (VSMPO) | BC2: Tecnodinamika (TDK) | BG2: L1 DETAILS | BJ2: ESTIMATION DETAILS | BN2: PRICE ANALYSIS
H3: Avi. Equip. | L3: Avitronic | P3: GIS | T3: IASL | X3: AEC | AB3: ADRYS | AF3: AZP | AJ3: EST | AN3: NASC | AR3: ROE | AV3: VEKS-M | AZ3: VSMPO | BD3: TDK
A4: Sl No | B4: IND. Sl. No. | C4: PART NO | D4: DESCRIPTION | E4: QTY | F4: Revised | G4: QTY | H4: Unit Price (USD) | J4: Total Price (USD) | K4: QTY | L4: Unit Price (USD) | N4: Total Price (USD) | O4: QTY | P4: Unit Price (USD) | R4: Total Price (USD) | S4: QTY | T4: Unit Price (USD) | V4: Total Price (USD) | W4: QTY | X4: Unit Price (USD) | Z4: Total Price (USD) | AA4: QTY | AB4: Unit Price (INR) | AD4: Total Price (INR) | AE4: QTY | AF4: Unit Price (USD) | AH4: Total Price (USD) | AI4: QTY | AJ4: Unit Price (INR) | AL4: Total Price (USD) | AM4: QTY | AN4: Unit Price (USD) | AP4: Total Price (USD) | AQ4: QTY | AR4: Unit Price (USD) | AT4: Total Price (USD) | AU4: QTY | AV4: VEKSM Unit Price (USD) | AX4: Total Price (USD) | AY4: QTY | AZ4: VEKSM Unit Price (USD) | BB4: Total Price (USD) | BC4: QTY | BD4: VEKSM Unit Price (USD) | BF4: Total Price (USD) | BG4: L1 AGENCY | BH4: OFFER TYPE | BI4: Total L1 PRICE (USD) | BJ4: REF Unit Price (USD) | BK4: REF SA | BL4: REF SA Date | BM4: EST Unit Basic Price (USD) @ 2024 level | BN4: L1 TOTAL BASIC VAL (USD) @ 2024 level | BO4: EST.TOTAL BASIC VAL (USD) @ 2024 level | BP4: Offered Price w.r.t Est Price (in%) | BQ4: Remarks
A5: 1 | B5: 1 | C5: X1 | D5: OPERATIONAL AMPLIFIER | E5: 7 | F5: 7 | O5: 7 | P5: 15.9 | R5: =IF(P5="TEC Rejected","",IF(P5="","",P5*IF(O5="",$E5,O5))) -> 111.3 | S5: 7 | T5: 27.5 | V5: =IF(T5="TEC Rejected","",IF(T5="","",T5*IF(S5="",$E5,S5))) -> 192.5 | Z5: =IF(X5="TEC Rejected","",IF(X5="","",X5*IF(W5="",$E5,W5))) | AA5: 7 | AB5: 915 | AD5: =IF(AB5="TEC Rejected","",IF(AB5="","",AB5*IF(AA5="",$E5,AA5))) -> 6405 | AH5: =IF(AF5="TEC Rejected","",IF(AF5="","",AF5*IF(AE5="",$E5,AE5))) | AL5: =IF(AJ5="TEC Rejected","",IF(AJ5="","",AJ5*IF(AI5="",$E5,AI5))) | AP5: =IF(AN5="TEC Rejected","",IF(AN5="","",AN5*IF(AM5="",$E5,AM5))) | AT5: =IF(AR5="TEC Rejected","",IF(AR5="","",AR5*IF(AQ5="",$E5,AQ5))) | AX5: =IF(AV5="TEC Rejected","",IF(AV5="","",AV5*IF(AU5="",$E5,AU5))) | BB5: =IF(AZ5="TEC Rejected","",IF(AZ5="","",AZ5*IF(AY5="",$E5,AY5))) | BF5: =IF(BD5="TEC Rejected","",IF(BD5="","",BD5*IF(BC5="",$E5,BC5)))
A6: 2 | B6: 2 | C6: X2 | D6: MICROCIRCUIT OF KOPYO RADAR | E6: 38 | F6: 38 | O6: 38 | P6: 17.1 | R6: =IF(P6="TEC Rejected","",IF(P6="","",P6*IF(O6="",$E6,O6))) -> 649.8 | S6: 38 | T6: 27.5 | V6: =IF(T6="TEC Rejected","",IF(T6="","",T6*IF(S6="",$E6,S6))) -> 1045 | Z6: =IF(X6="TEC Rejected","",IF(X6="","",X6*IF(W6="",$E6,W6))) | AA6: 38 | AB6: 915 | AD6: =IF(AB6="TEC Rejected","",IF(AB6="","",AB6*IF(AA6="",$E6,AA6))) -> 34770 | AH6: =IF(AF6="TEC Rejected","",IF(AF6="","",AF6*IF(AE6="",$E6,AE6))) | AL6: =IF(AJ6="TEC Rejected","",IF(AJ6="","",AJ6*IF(AI6="",$E6,AI6))) | AP6: =IF(AN6="TEC Rejected","",IF(AN6="","",AN6*IF(AM6="",$E6,AM6))) | AT6: =IF(AR6="TEC Rejected","",IF(AR6="","",AR6*IF(AQ6="",$E6,AQ6))) | AX6: =IF(AV6="TEC Rejected","",IF(AV6="","",AV6*IF(AU6="",$E6,AU6))) | BB6: =IF(AZ6="TEC Rejected","",IF(AZ6="","",AZ6*IF(AY6="",$E6,AY6))) | BF6: =IF(BD6="TEC Rejected","",IF(BD6="","",BD6*IF(BC6="",$E6,BC6)))
A7: 3 | B7: 3 | C7: X3 | D7: IC (Integrated Circuit ) | E7: 12 | F7: 12 | O7: 12 | P7: 16.5 | R7: =IF(P7="TEC Rejected","",IF(P7="","",P7*IF(O7="",$E7,O7))) -> 198 | S7: 12 | T7: 22 | V7: =IF(T7="TEC Rejected","",IF(T7="","",T7*IF(S7="",$E7,S7))) -> 264 | Z7: =IF(X7="TEC Rejected","",IF(X7="","",X7*IF(W7="",$E7,W7))) | AA7: 12 | AB7: 915 | AD7: =IF(AB7="TEC Rejected","",IF(AB7="","",AB7*IF(AA7="",$E7,AA7))) -> 10980 | AH7: =IF(AF7="TEC Rejected","",IF(AF7="","",AF7*IF(AE7="",$E7,AE7))) | AL7: =IF(AJ7="TEC Rejected","",IF(AJ7="","",AJ7*IF(AI7="",$E7,AI7))) | AP7: =IF(AN7="TEC Rejected","",IF(AN7="","",AN7*IF(AM7="",$E7,AM7))) | AT7: =IF(AR7="TEC Rejected","",IF(AR7="","",AR7*IF(AQ7="",$E7,AQ7))) | AX7: =IF(AV7="TEC Rejected","",IF(AV7="","",AV7*IF(AU7="",$E7,AU7))) | BB7: =IF(AZ7="TEC Rejected","",IF(AZ7="","",AZ7*IF(AY7="",$E7,AY7))) | BF7: =IF(BD7="TEC Rejected","",IF(BD7="","",BD7*IF(BC7="",$E7,BC7)))
A8: 4 | B8: 4 | C8: X4 | D8: MICROCIRCUIT | E8: 10 | F8: 10 | O8: 10 | P8: 12.6 | R8: =IF(P8="TEC Rejected","",IF(P8="","",P8*IF(O8="",$E8,O8))) -> 126 | S8: 10 | T8: 27.5 | V8: =IF(T8="TEC Rejected","",IF(T8="","",T8*IF(S8="",$E8,S8))) -> 275 | Z8: =IF(X8="TEC Rejected","",IF(X8="","",X8*IF(W8="",$E8,W8))) | AA8: 10 | AB8: 1215 | AD8: =IF(AB8="TEC Rejected","",IF(AB8="","",AB8*IF(AA8="",$E8,AA8))) -> 12150 | AH8: =IF(AF8="TEC Rejected","",IF(AF8="","",AF8*IF(AE8="",$E8,AE8))) | AL8: =IF(AJ8="TEC Rejected","",IF(AJ8="","",AJ8*IF(AI8="",$E8,AI8))) | AP8: =IF(AN8="TEC Rejected","",IF(AN8="","",AN8*IF(AM8="",$E8,AM8))) | AT8: =IF(AR8="TEC Rejected","",IF(AR8="","",AR8*IF(AQ8="",$E8,AQ8))) | AX8: =IF(AV8="TEC Rejected","",IF(AV8="","",AV8*IF(AU8="",$E8,AU8))) | BB8: =IF(AZ8="TEC Rejected","",IF(AZ8="","",AZ8*IF(AY8="",$E8,AY8))) | BF8: =IF(BD8="TEC Rejected","",IF(BD8="","",BD8*IF(BC8="",$E8,BC8)))
A9: 5 | B9: 5 | C9: X5 | D9: IC (Integrated Circuit ) | E9: 9 | F9: 9 | O9: 9 | P9: 15 | R9: =IF(P9="TEC Rejected","",IF(P9="","",P9*IF(O9="",$E9,O9))) -> 135 | S9: 9 | T9: 33 | V9: =IF(T9="TEC Rejected","",IF(T9="","",T9*IF(S9="",$E9,S9))) -> 297 | Z9: =IF(X9="TEC Rejected","",IF(X9="","",X9*IF(W9="",$E9,W9))) | AA9: 9 | AB9: 915 | AD9: =IF(AB9="TEC Rejected","",IF(AB9="","",AB9*IF(AA9="",$E9,AA9))) -> 8235 | AH9: =IF(AF9="TEC Rejected","",IF(AF9="","",AF9*IF(AE9="",$E9,AE9))) | AL9: =IF(AJ9="TEC Rejected","",IF(AJ9="","",AJ9*IF(AI9="",$E9,AI9))) | AP9: =IF(AN9="TEC Rejected","",IF(AN9="","",AN9*IF(AM9="",$E9,AM9))) | AT9: =IF(AR9="TEC Rejected","",IF(AR9="","",AR9*IF(AQ9="",$E9,AQ9))) | AX9: =IF(AV9="TEC Rejected","",IF(AV9="","",AV9*IF(AU9="",$E9,AU9))) | BB9: =IF(AZ9="TEC Rejected","",IF(AZ9="","",AZ9*IF(AY9="",$E9,AY9))) | BF9: =IF(BD9="TEC Rejected","",IF(BD9="","",BD9*IF(BC9="",$E9,BC9)))
A10: 6 | B10: 6 | C10: X6 | D10: DIODE | E10: 11 | F10: 11 | O10: 11 | P10: 3 | R10: =IF(P10="TEC Rejected","",IF(P10="","",P10*IF(O10="",$E10,O10))) -> 33 | S10: 11 | T10: 16.5 | V10: =IF(T10="TEC Rejected","",IF(T10="","",T10*IF(S10="",$E10,S10))) -> 181.5 | Z10: =IF(X10="TEC Rejected","",IF(X10="","",X10*IF(W10="",$E10,W10))) | AA10: 11 | AB10: 165 | AD10: =IF(AB10="TEC Rejected","",IF(AB10="","",AB10*IF(AA10="",$E10,AA10))) -> 1815 | AH10: =IF(AF10="TEC Rejected","",IF(AF10="","",AF10*IF(AE10="",$E10,AE10))) | AL10: =IF(AJ10="TEC Rejected","",IF(AJ10="","",AJ10*IF(AI10="",$E10,AI10))) | AP10: =IF(AN10="TEC Rejected","",IF(AN10="","",AN10*IF(AM10="",$E10,AM10))) | AT10: =IF(AR10="TEC Rejected","",IF(AR10="","",AR10*IF(AQ10="",$E10,AQ10))) | AX10: =IF(AV10="TEC Rejected","",IF(AV10="","",AV10*IF(AU10="",$E10,AU10))) | BB10: =IF(AZ10="TEC Rejected","",IF(AZ10="","",AZ10*IF(AY10="",$E10,AY10))) | BF10: =IF(BD10="TEC Rejected","",IF(BD10="","",BD10*IF(BC10="",$E10,BC10)))
A11: 7 | B11: 7 | C11: X7 | D11: TRANSISTOR | E11: 6 | F11: 6 | O11: 6 | P11: 9 | R11: =IF(P11="TEC Rejected","",IF(P11="","",P11*IF(O11="",$E11,O11))) -> 54 | S11: 6 | T11: 19.5 | V11: =IF(T11="TEC Rejected","",IF(T11="","",T11*IF(S11="",$E11,S11))) -> 117 | Z11: =IF(X11="TEC Rejected","",IF(X11="","",X11*IF(W11="",$E11,W11))) | AA11: 6 | AB11: 315 | AD11: =IF(AB11="TEC Rejected","",IF(AB11="","",AB11*IF(AA11="",$E11,AA11))) -> 1890 | AH11: =IF(AF11="TEC Rejected","",IF(AF11="","",AF11*IF(AE11="",$E11,AE11))) | AL11: =IF(AJ11="TEC Rejected","",IF(AJ11="","",AJ11*IF(AI11="",$E11,AI11))) | AP11: =IF(AN11="TEC Rejected","",IF(AN11="","",AN11*IF(AM11="",$E11,AM11))) | AT11: =IF(AR11="TEC Rejected","",IF(AR11="","",AR11*IF(AQ11="",$E11,AQ11))) | AX11: =IF(AV11="TEC Rejected","",IF(AV11="","",AV11*IF(AU11="",$E11,AU11))) | BB11: =IF(AZ11="TEC Rejected","",IF(AZ11="","",AZ11*IF(AY11="",$E11,AY11))) | BF11: =IF(BD11="TEC Rejected","",IF(BD11="","",BD11*IF(BC11="",$E11,BC11)))
A12: 8 | B12: 8 | C12: X8 | D12: TRANSISTOR | E12: 16 | F12: 16 | O12: 16 | P12: 18 | R12: =IF(P12="TEC Rejected","",IF(P12="","",P12*IF(O12="",$E12,O12))) -> 288 | S12: 16 | T12: 39.6 | V12: =IF(T12="TEC Rejected","",IF(T12="","",T12*IF(S12="",$E12,S12))) -> 633.6 | Z12: =IF(X12="TEC Rejected","",IF(X12="","",X12*IF(W12="",$E12,W12))) | AA12: 16 | AB12: 2865 | AD12: =IF(AB12="TEC Rejected","",IF(AB12="","",AB12*IF(AA12="",$E12,AA12))) -> 45840 | AH12: =IF(AF12="TEC Rejected","",IF(AF12="","",AF12*IF(AE12="",$E12,AE12))) | AL12: =IF(AJ12="TEC Rejected","",IF(AJ12="","",AJ12*IF(AI12="",$E12,AI12))) | AP12: =IF(AN12="TEC Rejected","",IF(AN12="","",AN12*IF(AM12="",$E12,AM12))) | AT12: =IF(AR12="TEC Rejected","",IF(AR12="","",AR12*IF(AQ12="",$E12,AQ12))) | AX12: =IF(AV12="TEC Rejected","",IF(AV12="","",AV12*IF(AU12="",$E12,AU12))) | BB12: =IF(AZ12="TEC Rejected","",IF(AZ12="","",AZ12*IF(AY12="",$E12,AY12))) | BF12: =IF(BD12="TEC Rejected","",IF(BD12="","",BD12*IF(BC12="",$E12,BC12)))
A13: 9 | B13: 9 | C13: X9 | D13: TRANSISTOR | E13: 17 | F13: 17 | O13: 17 | P13: 6.6 | R13: =IF(P13="TEC Rejected","",IF(P13="","",P13*IF(O13="",$E13,O13))) -> 112.2 | V13: =IF(T13="TEC Rejected","",IF(T13="","",T13*IF(S13="",$E13,S13))) | Z13: =IF(X13="TEC Rejected","",IF(X13="","",X13*IF(W13="",$E13,W13))) | AA13: 17 | AB13: 465 | AD13: =IF(AB13="TEC Rejected","",IF(AB13="","",AB13*IF(AA13="",$E13,AA13))) -> 7905 | AH13: =IF(AF13="TEC Rejected","",IF(AF13="","",AF13*IF(AE13="",$E13,AE13))) | AL13: =IF(AJ13="TEC Rejected","",IF(AJ13="","",AJ13*IF(AI13="",$E13,AI13))) | AP13: =IF(AN13="TEC Rejected","",IF(AN13="","",AN13*IF(AM13="",$E13,AM13))) | AT13: =IF(AR13="TEC Rejected","",IF(AR13="","",AR13*IF(AQ13="",$E13,AQ13))) | AX13: =IF(AV13="TEC Rejected","",IF(AV13="","",AV13*IF(AU13="",$E13,AU13))) | BB13: =IF(AZ13="TEC Rejected","",IF(AZ13="","",AZ13*IF(AY13="",$E13,AY13))) | BF13: =IF(BD13="TEC Rejected","",IF(BD13="","",BD13*IF(BC13="",$E13,BC13)))
A14: 10 | B14: 10 | C14: X10 | D14: IC (Integrated Circuit ) | E14: 30 | F14: 30 | O14: 30 | P14: 7.5 | R14: =IF(P14="TEC Rejected","",IF(P14="","",P14*IF(O14="",$E14,O14))) -> 225 | S14: 30 | T14: 36 | V14: =IF(T14="TEC Rejected","",IF(T14="","",T14*IF(S14="",$E14,S14))) -> 1080 | Z14: =IF(X14="TEC Rejected","",IF(X14="","",X14*IF(W14="",$E14,W14))) | AA14: 30 | AB14: 1065 | AD14: =IF(AB14="TEC Rejected","",IF(AB14="","",AB14*IF(AA14="",$E14,AA14))) -> 31950 | AH14: =IF(AF14="TEC Rejected","",IF(AF14="","",AF14*IF(AE14="",$E14,AE14))) | AL14: =IF(AJ14="TEC Rejected","",IF(AJ14="","",AJ14*IF(AI14="",$E14,AI14))) | AP14: =IF(AN14="TEC Rejected","",IF(AN14="","",AN14*IF(AM14="",$E14,AM14))) | AT14: =IF(AR14="TEC Rejected","",IF(AR14="","",AR14*IF(AQ14="",$E14,AQ14))) | AX14: =IF(AV14="TEC Rejected","",IF(AV14="","",AV14*IF(AU14="",$E14,AU14))) | BB14: =IF(AZ14="TEC Rejected","",IF(AZ14="","",AZ14*IF(AY14="",$E14,AY14))) | BF14: =IF(BD14="TEC Rejected","",IF(BD14="","",BD14*IF(BC14="",$E14,BC14)))
A15: 11 | B15: 11 | C15: X11 | D15: MOSFET | E15: 4 | F15: 4 | R15: =IF(P15="TEC Rejected","",IF(P15="","",P15*IF(O15="",$E15,O15))) | V15: =IF(T15="TEC Rejected","",IF(T15="","",T15*IF(S15="",$E15,S15))) | Z15: =IF(X15="TEC Rejected","",IF(X15="","",X15*IF(W15="",$E15,W15))) | AD15: =IF(AB15="TEC Rejected","",IF(AB15="","",AB15*IF(AA15="",$E15,AA15))) | AH15: =IF(AF15="TEC Rejected","",IF(AF15="","",AF15*IF(AE15="",$E15,AE15))) | AL15: =IF(AJ15="TEC Rejected","",IF(AJ15="","",AJ15*IF(AI15="",$E15,AI15))) | AP15: =IF(AN15="TEC Rejected","",IF(AN15="","",AN15*IF(AM15="",$E15,AM15))) | AT15: =IF(AR15="TEC Rejected","",IF(AR15="","",AR15*IF(AQ15="",$E15,AQ15))) | AX15: =IF(AV15="TEC Rejected","",IF(AV15="","",AV15*IF(AU15="",$E15,AU15))) | BB15: =IF(AZ15="TEC Rejected","",IF(AZ15="","",AZ15*IF(AY15="",$E15,AY15))) | BF15: =IF(BD15="TEC Rejected","",IF(BD15="","",BD15*IF(BC15="",$E15,BC15)))
A16: 12 | B16: 12 | C16: X12 | D16: IC (Integrated Circuit ) | E16: 12 | F16: 12 | O16: 12 | P16: 9 | R16: =IF(P16="TEC Rejected","",IF(P16="","",P16*IF(O16="",$E16,O16))) -> 108 | S16: 12 | T16: 29.7 | V16: =IF(T16="TEC Rejected","",IF(T16="","",T16*IF(S16="",$E16,S16))) -> 356.4 | Z16: =IF(X16="TEC Rejected","",IF(X16="","",X16*IF(W16="",$E16,W16))) | AA16: 12 | AB16: 765 | AD16: =IF(AB16="TEC Rejected","",IF(AB16="","",AB16*IF(AA16="",$E16,AA16))) -> 9180 | AH16: =IF(AF16="TEC Rejected","",IF(AF16="","",AF16*IF(AE16="",$E16,AE16))) | AL16: =IF(AJ16="TEC Rejected","",IF(AJ16="","",AJ16*IF(AI16="",$E16,AI16))) | AP16: =IF(AN16="TEC Rejected","",IF(AN16="","",AN16*IF(AM16="",$E16,AM16))) | AT16: =IF(AR16="TEC Rejected","",IF(AR16="","",AR16*IF(AQ16="",$E16,AQ16))) | AX16: =IF(AV16="TEC Rejected","",IF(AV16="","",AV16*IF(AU16="",$E16,AU16))) | BB16: =IF(AZ16="TEC Rejected","",IF(AZ16="","",AZ16*IF(AY16="",$E16,AY16))) | BF16: =IF(BD16="TEC Rejected","",IF(BD16="","",BD16*IF(BC16="",$E16,BC16)))
A17: 13 | B17: 13 | C17: X13 | D17: IC (Integrated Circuit ) | E17: 4 | F17: 4 | O17: 4 | P17: 8.1 | R17: =IF(P17="TEC Rejected","",IF(P17="","",P17*IF(O17="",$E17,O17))) -> 32.4 | S17: 4 | T17: 24 | V17: =IF(T17="TEC Rejected","",IF(T17="","",T17*IF(S17="",$E17,S17))) -> 96 | Z17: =IF(X17="TEC Rejected","",IF(X17="","",X17*IF(W17="",$E17,W17))) | AA17: 4 | AB17: 765 | AD17: =IF(AB17="TEC Rejected","",IF(AB17="","",AB17*IF(AA17="",$E17,AA17))) -> 3060 | AH17: =IF(AF17="TEC Rejected","",IF(AF17="","",AF17*IF(AE17="",$E17,AE17))) | AL17: =IF(AJ17="TEC Rejected","",IF(AJ17="","",AJ17*IF(AI17="",$E17,AI17))) | AP17: =IF(AN17="TEC Rejected","",IF(AN17="","",AN17*IF(AM17="",$E17,AM17))) | AT17: =IF(AR17="TEC Rejected","",IF(AR17="","",AR17*IF(AQ17="",$E17,AQ17))) | AX17: =IF(AV17="TEC Rejected","",IF(AV17="","",AV17*IF(AU17="",$E17,AU17))) | BB17: =IF(AZ17="TEC Rejected","",IF(AZ17="","",AZ17*IF(AY17="",$E17,AY17))) | BF17: =IF(BD17="TEC Rejected","",IF(BD17="","",BD17*IF(BC17="",$E17,BC17)))
A18: 14 | B18: 14 | C18: X14 | D18: IC (Integrated Circuit ) | E18: 10 | F18: 10 | O18: 10 | P18: 6 | R18: =IF(P18="TEC Rejected","",IF(P18="","",P18*IF(O18="",$E18,O18))) -> 60 | S18: 10 | T18: 24 | V18: =IF(T18="TEC Rejected","",IF(T18="","",T18*IF(S18="",$E18,S18))) -> 240 | Z18: =IF(X18="TEC Rejected","",IF(X18="","",X18*IF(W18="",$E18,W18))) | AA18: 10 | AB18: 765 | AD18: =IF(AB18="TEC Rejected","",IF(AB18="","",AB18*IF(AA18="",$E18,AA18))) -> 7650 | AH18: =IF(AF18="TEC Rejected","",IF(AF18="","",AF18*IF(AE18="",$E18,AE18))) | AL18: =IF(AJ18="TEC Rejected","",IF(AJ18="","",AJ18*IF(AI18="",$E18,AI18))) | AP18: =IF(AN18="TEC Rejected","",IF(AN18="","",AN18*IF(AM18="",$E18,AM18))) | AT18: =IF(AR18="TEC Rejected","",IF(AR18="","",AR18*IF(AQ18="",$E18,AQ18))) | AX18: =IF(AV18="TEC Rejected","",IF(AV18="","",AV18*IF(AU18="",$E18,AU18))) | BB18: =IF(AZ18="TEC Rejected","",IF(AZ18="","",AZ18*IF(AY18="",$E18,AY18))) | BF18: =IF(BD18="TEC Rejected","",IF(BD18="","",BD18*IF(BC18="",$E18,BC18)))
A19: 15 | B19: 15 | C19: X15 | D19: IC (Integrated Circuit ) | E19: 20 | F19: 20 | O19: 20 | P19: 6.6 | R19: =IF(P19="TEC Rejected","",IF(P19="","",P19*IF(O19="",$E19,O19))) -> 132 | S19: 20 | T19: 22 | V19: =IF(T19="TEC Rejected","",IF(T19="","",T19*IF(S19="",$E19,S19))) -> 440 | Z19: =IF(X19="TEC Rejected","",IF(X19="","",X19*IF(W19="",$E19,W19))) | AA19: 20 | AB19: 765 | AD19: =IF(AB19="TEC Rejected","",IF(AB19="","",AB19*IF(AA19="",$E19,AA19))) -> 15300 | AH19: =IF(AF19="TEC Rejected","",IF(AF19="","",AF19*IF(AE19="",$E19,AE19))) | AL19: =IF(AJ19="TEC Rejected","",IF(AJ19="","",AJ19*IF(AI19="",$E19,AI19))) | AP19: =IF(AN19="TEC Rejected","",IF(AN19="","",AN19*IF(AM19="",$E19,AM19))) | AT19: =IF(AR19="TEC Rejected","",IF(AR19="","",AR19*IF(AQ19="",$E19,AQ19))) | AX19: =IF(AV19="TEC Rejected","",IF(AV19="","",AV19*IF(AU19="",$E19,AU19))) | BB19: =IF(AZ19="TEC Rejected","",IF(AZ19="","",AZ19*IF(AY19="",$E19,AY19))) | BF19: =IF(BD19="TEC Rejected","",IF(BD19="","",BD19*IF(BC19="",$E19,BC19)))
A20: 16 | B20: 16 | C20: X16 | D20: IC (Integrated Circuit ) | E20: 15 | F20: 15 | O20: 15 | P20: 88 | R20: =IF(P20="TEC Rejected","",IF(P20="","",P20*IF(O20="",$E20,O20))) -> 1320 | S20: 15 | T20: 42 | V20: =IF(T20="TEC Rejected","",IF(T20="","",T20*IF(S20="",$E20,S20))) -> 630 | Z20: =IF(X20="TEC Rejected","",IF(X20="","",X20*IF(W20="",$E20,W20))) | AA20: 15 | AB20: 2265 | AD20: =IF(AB20="TEC Rejected","",IF(AB20="","",AB20*IF(AA20="",$E20,AA20))) -> 33975 | AH20: =IF(AF20="TEC Rejected","",IF(AF20="","",AF20*IF(AE20="",$E20,AE20))) | AL20: =IF(AJ20="TEC Rejected","",IF(AJ20="","",AJ20*IF(AI20="",$E20,AI20))) | AP20: =IF(AN20="TEC Rejected","",IF(AN20="","",AN20*IF(AM20="",$E20,AM20))) | AT20: =IF(AR20="TEC Rejected","",IF(AR20="","",AR20*IF(AQ20="",$E20,AQ20))) | AX20: =IF(AV20="TEC Rejected","",IF(AV20="","",AV20*IF(AU20="",$E20,AU20))) | BB20: =IF(AZ20="TEC Rejected","",IF(AZ20="","",AZ20*IF(AY20="",$E20,AY20))) | BF20: =IF(BD20="TEC Rejected","",IF(BD20="","",BD20*IF(BC20="",$E20,BC20)))
A21: 17 | B21: 17 | C21: X17 | D21: IC (Integrated Circuit ) | E21: 34 | F21: 34 | O21: 34 | P21: 15 | R21: =IF(P21="TEC Rejected","",IF(P21="","",P21*IF(O21="",$E21,O21))) -> 510 | S21: 34 | T21: 24 | V21: =IF(T21="TEC Rejected","",IF(T21="","",T21*IF(S21="",$E21,S21))) -> 816 | Z21: =IF(X21="TEC Rejected","",IF(X21="","",X21*IF(W21="",$E21,W21))) | AA21: 34 | AB21: 1215 | AD21: =IF(AB21="TEC Rejected","",IF(AB21="","",AB21*IF(AA21="",$E21,AA21))) -> 41310 | AH21: =IF(AF21="TEC Rejected","",IF(AF21="","",AF21*IF(AE21="",$E21,AE21))) | AL21: =IF(AJ21="TEC Rejected","",IF(AJ21="","",AJ21*IF(AI21="",$E21,AI21))) | AP21: =IF(AN21="TEC Rejected","",IF(AN21="","",AN21*IF(AM21="",$E21,AM21))) | AT21: =IF(AR21="TEC Rejected","",IF(AR21="","",AR21*IF(AQ21="",$E21,AQ21))) | AX21: =IF(AV21="TEC Rejected","",IF(AV21="","",AV21*IF(AU21="",$E21,AU21))) | BB21: =IF(AZ21="TEC Rejected","",IF(AZ21="","",AZ21*IF(AY21="",$E21,AY21))) | BF21: =IF(BD21="TEC Rejected","",IF(BD21="","",BD21*IF(BC21="",$E21,BC21)))
A22: 18 | B22: 18 | C22: X18 | D22: IC (Integrated Circuit ) | E22: 11 | F22: 11 | R22: =IF(P22="TEC Rejected","",IF(P22="","",P22*IF(O22="",$E22,O22))) | V22: =IF(T22="TEC Rejected","",IF(T22="","",T22*IF(S22="",$E22,S22))) | Z22: =IF(X22="TEC Rejected","",IF(X22="","",X22*IF(W22="",$E22,W22))) | AD22: =IF(AB22="TEC Rejected","",IF(AB22="","",AB22*IF(AA22="",$E22,AA22))) | AH22: =IF(AF22="TEC Rejected","",IF(AF22="","",AF22*IF(AE22="",$E22,AE22))) | AL22: =IF(AJ22="TEC Rejected","",IF(AJ22="","",AJ22*IF(AI22="",$E22,AI22))) | AP22: =IF(AN22="TEC Rejected","",IF(AN22="","",AN22*IF(AM22="",$E22,AM22))) | AT22: =IF(AR22="TEC Rejected","",IF(AR22="","",AR22*IF(AQ22="",$E22,AQ22))) | AX22: =IF(AV22="TEC Rejected","",IF(AV22="","",AV22*IF(AU22="",$E22,AU22))) | BB22: =IF(AZ22="TEC Rejected","",IF(AZ22="","",AZ22*IF(AY22="",$E22,AY22))) | BF22: =IF(BD22="TEC Rejected","",IF(BD22="","",BD22*IF(BC22="",$E22,BC22)))
A23: 19 | B23: 19 | C23: X19 | D23: CIRCUIT BREAKER | E23: 13 | F23: 13 | O23: 13 | P23: 450 | R23: =IF(P23="TEC Rejected","",IF(P23="","",P23*IF(O23="",$E23,O23))) -> 5850 | S23: 13 | T23: 377 | V23: =IF(T23="TEC Rejected","",IF(T23="","",T23*IF(S23="",$E23,S23))) -> 4901 | Z23: =IF(X23="TEC Rejected","",IF(X23="","",X23*IF(W23="",$E23,W23))) | AA23: 13 | AB23: 7365 | AD23: =IF(AB23="TEC Rejected","",IF(AB23="","",AB23*IF(AA23="",$E23,AA23))) -> 95745 | AH23: =IF(AF23="TEC Rejected","",IF(AF23="","",AF23*IF(AE23="",$E23,AE23))) | AI23: 13 | AJ23: 20750 | AL23: =IF(AJ23="TEC Rejected","",IF(AJ23="","",AJ23*IF(AI23="",$E23,AI23))) -> 269750 | AP23: =IF(AN23="TEC Rejected","",IF(AN23="","",AN23*IF(AM23="",$E23,AM23))) | AT23: =IF(AR23="TEC Rejected","",IF(AR23="","",AR23*IF(AQ23="",$E23,AQ23))) | AX23: =IF(AV23="TEC Rejected","",IF(AV23="","",AV23*IF(AU23="",$E23,AU23))) | BB23: =IF(AZ23="TEC Rejected","",IF(AZ23="","",AZ23*IF(AY23="",$E23,AY23))) | BF23: =IF(BD23="TEC Rejected","",IF(BD23="","",BD23*IF(BC23="",$E23,BC23)))
A24: 20 | B24: 20 | C24: X20 | D24: COLLIMATOR HEAD KG-3R-4M2 | E24: 4 | F24: 4 | R24: =IF(P24="TEC Rejected","",IF(P24="","",P24*IF(O24="",$E24,O24))) | V24: =IF(T24="TEC Rejected","",IF(T24="","",T24*IF(S24="",$E24,S24))) | Z24: =IF(X24="TEC Rejected","",IF(X24="","",X24*IF(W24="",$E24,W24))) | AD24: =IF(AB24="TEC Rejected","",IF(AB24="","",AB24*IF(AA24="",$E24,AA24))) | AH24: =IF(AF24="TEC Rejected","",IF(AF24="","",AF24*IF(AE24="",$E24,AE24))) | AL24: =IF(AJ24="TEC Rejected","",IF(AJ24="","",AJ24*IF(AI24="",$E24,AI24))) | AP24: =IF(AN24="TEC Rejected","",IF(AN24="","",AN24*IF(AM24="",$E24,AM24))) | AT24: =IF(AR24="TEC Rejected","",IF(AR24="","",AR24*IF(AQ24="",$E24,AQ24))) | AX24: =IF(AV24="TEC Rejected","",IF(AV24="","",AV24*IF(AU24="",$E24,AU24))) | BB24: =IF(AZ24="TEC Rejected","",IF(AZ24="","",AZ24*IF(AY24="",$E24,AY24))) | BF24: =IF(BD24="TEC Rejected","",IF(BD24="","",BD24*IF(BC24="",$E24,BC24)))
A25: 21 | B25: 21 | C25: X21 | D25: 27V LAMP FOR RET ASSIY | E25: 9 | F25: 9 | R25: =IF(P25="TEC Rejected","",IF(P25="","",P25*IF(O25="",$E25,O25))) | V25: =IF(T25="TEC Rejected","",IF(T25="","",T25*IF(S25="",$E25,S25))) | Z25: =IF(X25="TEC Rejected","",IF(X25="","",X25*IF(W25="",$E25,W25))) | AD25: =IF(AB25="TEC Rejected","",IF(AB25="","",AB25*IF(AA25="",$E25,AA25))) | AH25: =IF(AF25="TEC Rejected","",IF(AF25="","",AF25*IF(AE25="",$E25,AE25))) | AL25: =IF(AJ25="TEC Rejected","",IF(AJ25="","",AJ25*IF(AI25="",$E25,AI25))) | AP25: =IF(AN25="TEC Rejected","",IF(AN25="","",AN25*IF(AM25="",$E25,AM25))) | AT25: =IF(AR25="TEC Rejected","",IF(AR25="","",AR25*IF(AQ25="",$E25,AQ25))) | AX25: =IF(AV25="TEC Rejected","",IF(AV25="","",AV25*IF(AU25="",$E25,AU25))) | BB25: =IF(AZ25="TEC Rejected","",IF(AZ25="","",AZ25*IF(AY25="",$E25,AY25))) | BF25: =IF(BD25="TEC Rejected","",IF(BD25="","",BD25*IF(BC25="",$E25,BC25)))
A26: 22 | B26: 22 | C26: X22 | D26: PHOTO RESISTOR | E26: 9 | F26: 9 | R26: =IF(P26="TEC Rejected","",IF(P26="","",P26*IF(O26="",$E26,O26))) | V26: =IF(T26="TEC Rejected","",IF(T26="","",T26*IF(S26="",$E26,S26))) | Z26: =IF(X26="TEC Rejected","",IF(X26="","",X26*IF(W26="",$E26,W26))) | AD26: =IF(AB26="TEC Rejected","",IF(AB26="","",AB26*IF(AA26="",$E26,AA26))) | AH26: =IF(AF26="TEC Rejected","",IF(AF26="","",AF26*IF(AE26="",$E26,AE26))) | AL26: =IF(AJ26="TEC Rejected","",IF(AJ26="","",AJ26*IF(AI26="",$E26,AI26))) | AP26: =IF(AN26="TEC Rejected","",IF(AN26="","",AN26*IF(AM26="",$E26,AM26))) | AT26: =IF(AR26="TEC Rejected","",IF(AR26="","",AR26*IF(AQ26="",$E26,AQ26))) | AX26: =IF(AV26="TEC Rejected","",IF(AV26="","",AV26*IF(AU26="",$E26,AU26))) | BB26: =IF(AZ26="TEC Rejected","",IF(AZ26="","",AZ26*IF(AY26="",$E26,AY26))) | BF26: =IF(BD26="TEC Rejected","",IF(BD26="","",BD26*IF(BC26="",$E26,BC26)))
A27: 23 | B27: 23 | C27: X23 | D27: SECURING NUT | E27: 11 | F27: 11 | R27: =IF(P27="TEC Rejected","",IF(P27="","",P27*IF(O27="",$E27,O27))) | V27: =IF(T27="TEC Rejected","",IF(T27="","",T27*IF(S27="",$E27,S27))) | Z27: =IF(X27="TEC Rejected","",IF(X27="","",X27*IF(W27="",$E27,W27))) | AD27: =IF(AB27="TEC Rejected","",IF(AB27="","",AB27*IF(AA27="",$E27,AA27))) | AH27: =IF(AF27="TEC Rejected","",IF(AF27="","",AF27*IF(AE27="",$E27,AE27))) | AL27: =IF(AJ27="TEC Rejected","",IF(AJ27="","",AJ27*IF(AI27="",$E27,AI27))) | AP27: =IF(AN27="TEC Rejected","",IF(AN27="","",AN27*IF(AM27="",$E27,AM27))) | AT27: =IF(AR27="TEC Rejected","",IF(AR27="","",AR27*IF(AQ27="",$E27,AQ27))) | AX27: =IF(AV27="TEC Rejected","",IF(AV27="","",AV27*IF(AU27="",$E27,AU27))) | BB27: =IF(AZ27="TEC Rejected","",IF(AZ27="","",AZ27*IF(AY27="",$E27,AY27))) | BF27: =IF(BD27="TEC Rejected","",IF(BD27="","",BD27*IF(BC27="",$E27,BC27)))
A28: 24 | B28: 24 | C28: X24 | D28: DIODE | E28: 46 | F28: 46 | O28: 46 | P28: 3.6 | R28: =IF(P28="TEC Rejected","",IF(P28="","",P28*IF(O28="",$E28,O28))) -> 165.6 | S28: 46 | T28: 9.6 | V28: =IF(T28="TEC Rejected","",IF(T28="","",T28*IF(S28="",$E28,S28))) -> 441.6 | Z28: =IF(X28="TEC Rejected","",IF(X28="","",X28*IF(W28="",$E28,W28))) | AA28: 46 | AB28: 90 | AD28: =IF(AB28="TEC Rejected","",IF(AB28="","",AB28*IF(AA28="",$E28,AA28))) -> 4140 | AH28: =IF(AF28="TEC Rejected","",IF(AF28="","",AF28*IF(AE28="",$E28,AE28))) | AL28: =IF(AJ28="TEC Rejected","",IF(AJ28="","",AJ28*IF(AI28="",$E28,AI28))) | AP28: =IF(AN28="TEC Rejected","",IF(AN28="","",AN28*IF(AM28="",$E28,AM28))) | AT28: =IF(AR28="TEC Rejected","",IF(AR28="","",AR28*IF(AQ28="",$E28,AQ28))) | AX28: =IF(AV28="TEC Rejected","",IF(AV28="","",AV28*IF(AU28="",$E28,AU28))) | BB28: =IF(AZ28="TEC Rejected","",IF(AZ28="","",AZ28*IF(AY28="",$E28,AY28))) | BF28: =IF(BD28="TEC Rejected","",IF(BD28="","",BD28*IF(BC28="",$E28,BC28)))
A29: 25 | B29: 25 | C29: X25 | D29: DIODE | E29: 20 | F29: 20 | O29: 20 | P29: 3.6 | R29: =IF(P29="TEC Rejected","",IF(P29="","",P29*IF(O29="",$E29,O29))) -> 72 | S29: 20 | T29: 8.8 | V29: =IF(T29="TEC Rejected","",IF(T29="","",T29*IF(S29="",$E29,S29))) -> 176 | Z29: =IF(X29="TEC Rejected","",IF(X29="","",X29*IF(W29="",$E29,W29))) | AA29: 20 | AB29: 90 | AD29: =IF(AB29="TEC Rejected","",IF(AB29="","",AB29*IF(AA29="",$E29,AA29))) -> 1800 | AH29: =IF(AF29="TEC Rejected","",IF(AF29="","",AF29*IF(AE29="",$E29,AE29))) | AL29: =IF(AJ29="TEC Rejected","",IF(AJ29="","",AJ29*IF(AI29="",$E29,AI29))) | AP29: =IF(AN29="TEC Rejected","",IF(AN29="","",AN29*IF(AM29="",$E29,AM29))) | AT29: =IF(AR29="TEC Rejected","",IF(AR29="","",AR29*IF(AQ29="",$E29,AQ29))) | AX29: =IF(AV29="TEC Rejected","",IF(AV29="","",AV29*IF(AU29="",$E29,AU29))) | BB29: =IF(AZ29="TEC Rejected","",IF(AZ29="","",AZ29*IF(AY29="",$E29,AY29))) | BF29: =IF(BD29="TEC Rejected","",IF(BD29="","",BD29*IF(BC29="",$E29,BC29)))
A30: 26 | B30: 26 | C30: X26 | D30: MOTOR | E30: 5 | F30: 5 | O30: 5 | P30: 4583 | R30: =IF(P30="TEC Rejected","",IF(P30="","",P30*IF(O30="",$E30,O30))) -> 22915 | S30: 5 | T30: 4920 | V30: =IF(T30="TEC Rejected","",IF(T30="","",T30*IF(S30="",$E30,S30))) -> 24600 | Z30: =IF(X30="TEC Rejected","",IF(X30="","",X30*IF(W30="",$E30,W30))) | AD30: =IF(AB30="TEC Rejected","",IF(AB30="","",AB30*IF(AA30="",$E30,AA30))) | AH30: =IF(AF30="TEC Rejected","",IF(AF30="","",AF30*IF(AE30="",$E30,AE30))) | AL30: =IF(AJ30="TEC Rejected","",IF(AJ30="","",AJ30*IF(AI30="",$E30,AI30))) | AP30: =IF(AN30="TEC Rejected","",IF(AN30="","",AN30*IF(AM30="",$E30,AM30))) | AT30: =IF(AR30="TEC Rejected","",IF(AR30="","",AR30*IF(AQ30="",$E30,AQ30))) | AX30: =IF(AV30="TEC Rejected","",IF(AV30="","",AV30*IF(AU30="",$E30,AU30))) | BB30: =IF(AZ30="TEC Rejected","",IF(AZ30="","",AZ30*IF(AY30="",$E30,AY30))) | BF30: =IF(BD30="TEC Rejected","",IF(BD30="","",BD30*IF(BC30="",$E30,BC30)))
A31: 27 | B31: 27 | C31: X27 | D31: FUSE HOLDER | E31: 121 | F31: 121 | O31: 121 | P31: 6.5 | R31: =IF(P31="TEC Rejected","",IF(P31="","",P31*IF(O31="",$E31,O31))) -> 786.5 | S31: 121 | T31: 23.1 | V31: =IF(T31="TEC Rejected","",IF(T31="","",T31*IF(S31="",$E31,S31))) -> 2795.1 | Z31: =IF(X31="TEC Rejected","",IF(X31="","",X31*IF(W31="",$E31,W31))) | AA31: 121 | AB31: 465 | AD31: =IF(AB31="TEC Rejected","",IF(AB31="","",AB31*IF(AA31="",$E31,AA31))) -> 56265 | AH31: =IF(AF31="TEC Rejected","",IF(AF31="","",AF31*IF(AE31="",$E31,AE31))) | AI31: 121 | AJ31: 581 | AL31: =IF(AJ31="TEC Rejected","",IF(AJ31="","",AJ31*IF(AI31="",$E31,AI31))) -> 70301 | AP31: =IF(AN31="TEC Rejected","",IF(AN31="","",AN31*IF(AM31="",$E31,AM31))) | AT31: =IF(AR31="TEC Rejected","",IF(AR31="","",AR31*IF(AQ31="",$E31,AQ31))) | AX31: =IF(AV31="TEC Rejected","",IF(AV31="","",AV31*IF(AU31="",$E31,AU31))) | BB31: =IF(AZ31="TEC Rejected","",IF(AZ31="","",AZ31*IF(AY31="",$E31,AY31))) | BF31: =IF(BD31="TEC Rejected","",IF(BD31="","",BD31*IF(BC31="",$E31,BC31)))
A32: 28 | B32: 28 | C32: X28 | D32: HIGH VOLTAGE SEALENT | E32: 15 | F32: 15 | R32: =IF(P32="TEC Rejected","",IF(P32="","",P32*IF(O32="",$E32,O32))) | V32: =IF(T32="TEC Rejected","",IF(T32="","",T32*IF(S32="",$E32,S32))) | Z32: =IF(X32="TEC Rejected","",IF(X32="","",X32*IF(W32="",$E32,W32))) | AD32: =IF(AB32="TEC Rejected","",IF(AB32="","",AB32*IF(AA32="",$E32,AA32))) | AH32: =IF(AF32="TEC Rejected","",IF(AF32="","",AF32*IF(AE32="",$E32,AE32))) | AL32: =IF(AJ32="TEC Rejected","",IF(AJ32="","",AJ32*IF(AI32="",$E32,AI32))) | AP32: =IF(AN32="TEC Rejected","",IF(AN32="","",AN32*IF(AM32="",$E32,AM32))) | AT32: =IF(AR32="TEC Rejected","",IF(AR32="","",AR32*IF(AQ32="",$E32,AQ32))) | AX32: =IF(AV32="TEC Rejected","",IF(AV32="","",AV32*IF(AU32="",$E32,AU32))) | BB32: =IF(AZ32="TEC Rejected","",IF(AZ32="","",AZ32*IF(AY32="",$E32,AY32))) | BF32: =IF(BD32="TEC Rejected","",IF(BD32="","",BD32*IF(BC32="",$E32,BC32)))
A33: 29 | B33: 29 | C33: X29 | D33: ELECTRIC TIMER | E33: 3 | F33: 3 | R33: =IF(P33="TEC Rejected","",IF(P33="","",P33*IF(O33="",$E33,O33))) | V33: =IF(T33="TEC Rejected","",IF(T33="","",T33*IF(S33="",$E33,S33))) | Z33: =IF(X33="TEC Rejected","",IF(X33="","",X33*IF(W33="",$E33,W33))) | AA33: 3 | AB33: 3765 | AD33: =IF(AB33="TEC Rejected","",IF(AB33="","",AB33*IF(AA33="",$E33,AA33))) -> 11295 | AH33: =IF(AF33="TEC Rejected","",IF(AF33="","",AF33*IF(AE33="",$E33,AE33))) | AL33: =IF(AJ33="TEC Rejected","",IF(AJ33="","",AJ33*IF(AI33="",$E33,AI33))) | AP33: =IF(AN33="TEC Rejected","",IF(AN33="","",AN33*IF(AM33="",$E33,AM33))) | AT33: =IF(AR33="TEC Rejected","",IF(AR33="","",AR33*IF(AQ33="",$E33,AQ33))) | AX33: =IF(AV33="TEC Rejected","",IF(AV33="","",AV33*IF(AU33="",$E33,AU33))) | BB33: =IF(AZ33="TEC Rejected","",IF(AZ33="","",AZ33*IF(AY33="",$E33,AY33))) | BF33: =IF(BD33="TEC Rejected","",IF(BD33="","",BD33*IF(BC33="",$E33,BC33)))
A34: 30 | B34: 30 | C34: X30 | D34: UNIT 08-11 UFTI / FORMER | E34: 4 | F34: 4 | R34: =IF(P34="TEC Rejected","",IF(P34="","",P34*IF(O34="",$E34,O34))) | V34: =IF(T34="TEC Rejected","",IF(T34="","",T34*IF(S34="",$E34,S34))) | Z34: =IF(X34="TEC Rejected","",IF(X34="","",X34*IF(W34="",$E34,W34))) | AD34: =IF(AB34="TEC Rejected","",IF(AB34="","",AB34*IF(AA34="",$E34,AA34))) | AH34: =IF(AF34="TEC Rejected","",IF(AF34="","",AF34*IF(AE34="",$E34,AE34))) | AL34: =IF(AJ34="TEC Rejected","",IF(AJ34="","",AJ34*IF(AI34="",$E34,AI34))) | AP34: =IF(AN34="TEC Rejected","",IF(AN34="","",AN34*IF(AM34="",$E34,AM34))) | AT34: =IF(AR34="TEC Rejected","",IF(AR34="","",AR34*IF(AQ34="",$E34,AQ34))) | AX34: =IF(AV34="TEC Rejected","",IF(AV34="","",AV34*IF(AU34="",$E34,AU34))) | BB34: =IF(AZ34="TEC Rejected","",IF(AZ34="","",AZ34*IF(AY34="",$E34,AY34))) | BF34: =IF(BD34="TEC Rejected","",IF(BD34="","",BD34*IF(BC34="",$E34,BC34)))
A35: 31 | B35: 31 | C35: X31 | D35: CAPACITOR | E35: 10 | F35: 10 | O35: 10 | P35: 30 | R35: =IF(P35="TEC Rejected","",IF(P35="","",P35*IF(O35="",$E35,O35))) -> 300 | S35: 10 | T35: 14.4 | V35: =IF(T35="TEC Rejected","",IF(T35="","",T35*IF(S35="",$E35,S35))) -> 144 | Z35: =IF(X35="TEC Rejected","",IF(X35="","",X35*IF(W35="",$E35,W35))) | AA35: 10 | AB35: 315 | AD35: =IF(AB35="TEC Rejected","",IF(AB35="","",AB35*IF(AA35="",$E35,AA35))) -> 3150 | AH35: =IF(AF35="TEC Rejected","",IF(AF35="","",AF35*IF(AE35="",$E35,AE35))) | AL35: =IF(AJ35="TEC Rejected","",IF(AJ35="","",AJ35*IF(AI35="",$E35,AI35))) | AP35: =IF(AN35="TEC Rejected","",IF(AN35="","",AN35*IF(AM35="",$E35,AM35))) | AT35: =IF(AR35="TEC Rejected","",IF(AR35="","",AR35*IF(AQ35="",$E35,AQ35))) | AX35: =IF(AV35="TEC Rejected","",IF(AV35="","",AV35*IF(AU35="",$E35,AU35))) | BB35: =IF(AZ35="TEC Rejected","",IF(AZ35="","",AZ35*IF(AY35="",$E35,AY35))) | BF35: =IF(BD35="TEC Rejected","",IF(BD35="","",BD35*IF(BC35="",$E35,BC35)))
A36: 32 | B36: 32 | C36: X32 | D36: CAPACITOR | E36: 20 | F36: 20 | O36: 20 | P36: 30 | R36: =IF(P36="TEC Rejected","",IF(P36="","",P36*IF(O36="",$E36,O36))) -> 600 | S36: 20 | T36: 14.4 | V36: =IF(T36="TEC Rejected","",IF(T36="","",T36*IF(S36="",$E36,S36))) -> 288 | Z36: =IF(X36="TEC Rejected","",IF(X36="","",X36*IF(W36="",$E36,W36))) | AA36: 20 | AB36: 315 | AD36: =IF(AB36="TEC Rejected","",IF(AB36="","",AB36*IF(AA36="",$E36,AA36))) -> 6300 | AH36: =IF(AF36="TEC Rejected","",IF(AF36="","",AF36*IF(AE36="",$E36,AE36))) | AL36: =IF(AJ36="TEC Rejected","",IF(AJ36="","",AJ36*IF(AI36="",$E36,AI36))) | AP36: =IF(AN36="TEC Rejected","",IF(AN36="","",AN36*IF(AM36="",$E36,AM36))) | AT36: =IF(AR36="TEC Rejected","",IF(AR36="","",AR36*IF(AQ36="",$E36,AQ36))) | AX36: =IF(AV36="TEC Rejected","",IF(AV36="","",AV36*IF(AU36="",$E36,AU36))) | BB36: =IF(AZ36="TEC Rejected","",IF(AZ36="","",AZ36*IF(AY36="",$E36,AY36))) | BF36: =IF(BD36="TEC Rejected","",IF(BD36="","",BD36*IF(BC36="",$E36,BC36)))
A37: 33 | B37: 33 | C37: X33 | D37: CAPACITOR | E37: 110 | F37: 110 | O37: 110 | P37: 27 | R37: =IF(P37="TEC Rejected","",IF(P37="","",P37*IF(O37="",$E37,O37))) -> 2970 | S37: 110 | T37: 19.5 | V37: =IF(T37="TEC Rejected","",IF(T37="","",T37*IF(S37="",$E37,S37))) -> 2145 | Z37: =IF(X37="TEC Rejected","",IF(X37="","",X37*IF(W37="",$E37,W37))) | AA37: 110 | AB37: 465 | AD37: =IF(AB37="TEC Rejected","",IF(AB37="","",AB37*IF(AA37="",$E37,AA37))) -> 51150 | AH37: =IF(AF37="TEC Rejected","",IF(AF37="","",AF37*IF(AE37="",$E37,AE37))) | AL37: =IF(AJ37="TEC Rejected","",IF(AJ37="","",AJ37*IF(AI37="",$E37,AI37))) | AP37: =IF(AN37="TEC Rejected","",IF(AN37="","",AN37*IF(AM37="",$E37,AM37))) | AT37: =IF(AR37="TEC Rejected","",IF(AR37="","",AR37*IF(AQ37="",$E37,AQ37))) | AX37: =IF(AV37="TEC Rejected","",IF(AV37="","",AV37*IF(AU37="",$E37,AU37))) | BB37: =IF(AZ37="TEC Rejected","",IF(AZ37="","",AZ37*IF(AY37="",$E37,AY37))) | BF37: =IF(BD37="TEC Rejected","",IF(BD37="","",BD37*IF(BC37="",$E37,BC37)))
A38: 34 | B38: 34 | C38: X34 | D38: CAPACITOR | E38: 131 | F38: 131 | O38: 131 | P38: 45 | R38: =IF(P38="TEC Rejected","",IF(P38="","",P38*IF(O38="",$E38,O38))) -> 5895 | S38: 131 | T38: 18 | V38: =IF(T38="TEC Rejected","",IF(T38="","",T38*IF(S38="",$E38,S38))) -> 2358 | Z38: =IF(X38="TEC Rejected","",IF(X38="","",X38*IF(W38="",$E38,W38))) | AA38: 131 | AB38: 465 | AD38: =IF(AB38="TEC Rejected","",IF(AB38="","",AB38*IF(AA38="",$E38,AA38))) -> 60915 | AH38: =IF(AF38="TEC Rejected","",IF(AF38="","",AF38*IF(AE38="",$E38,AE38))) | AL38: =IF(AJ38="TEC Rejected","",IF(AJ38="","",AJ38*IF(AI38="",$E38,AI38))) | AP38: =IF(AN38="TEC Rejected","",IF(AN38="","",AN38*IF(AM38="",$E38,AM38))) | AT38: =IF(AR38="TEC Rejected","",IF(AR38="","",AR38*IF(AQ38="",$E38,AQ38))) | AX38: =IF(AV38="TEC Rejected","",IF(AV38="","",AV38*IF(AU38="",$E38,AU38))) | BB38: =IF(AZ38="TEC Rejected","",IF(AZ38="","",AZ38*IF(AY38="",$E38,AY38))) | BF38: =IF(BD38="TEC Rejected","",IF(BD38="","",BD38*IF(BC38="",$E38,BC38)))
A39: 35 | B39: 35 | C39: X35 | D39: CAPACITOR | E39: 10 | F39: 10 | O39: 10 | P39: 171 | R39: =IF(P39="TEC Rejected","",IF(P39="","",P39*IF(O39="",$E39,O39))) -> 1710 | S39: 10 | T39: 144 | V39: =IF(T39="TEC Rejected","",IF(T39="","",T39*IF(S39="",$E39,S39))) -> 1440 | Z39: =IF(X39="TEC Rejected","",IF(X39="","",X39*IF(W39="",$E39,W39))) | AA39: 10 | AB39: 9765 | AD39: =IF(AB39="TEC Rejected","",IF(AB39="","",AB39*IF(AA39="",$E39,AA39))) -> 97650 | AH39: =IF(AF39="TEC Rejected","",IF(AF39="","",AF39*IF(AE39="",$E39,AE39))) | AI39: 10 | AJ39: 14940 | AL39: =IF(AJ39="TEC Rejected","",IF(AJ39="","",AJ39*IF(AI39="",$E39,AI39))) -> 149400 | AP39: =IF(AN39="TEC Rejected","",IF(AN39="","",AN39*IF(AM39="",$E39,AM39))) | AT39: =IF(AR39="TEC Rejected","",IF(AR39="","",AR39*IF(AQ39="",$E39,AQ39))) | AX39: =IF(AV39="TEC Rejected","",IF(AV39="","",AV39*IF(AU39="",$E39,AU39))) | BB39: =IF(AZ39="TEC Rejected","",IF(AZ39="","",AZ39*IF(AY39="",$E39,AY39))) | BF39: =IF(BD39="TEC Rejected","",IF(BD39="","",BD39*IF(BC39="",$E39,BC39)))
A40: 36 | B40: 36 | C40: X36 | D40: CAPACITOR | E40: 28 | F40: 28 | O40: 28 | P40: 155 | R40: =IF(P40="TEC Rejected","",IF(P40="","",P40*IF(O40="",$E40,O40))) -> 4340 | S40: 28 | T40: 132 | V40: =IF(T40="TEC Rejected","",IF(T40="","",T40*IF(S40="",$E40,S40))) -> 3696 | Z40: =IF(X40="TEC Rejected","",IF(X40="","",X40*IF(W40="",$E40,W40))) | AA40: 28 | AB40: 9765 | AD40: =IF(AB40="TEC Rejected","",IF(AB40="","",AB40*IF(AA40="",$E40,AA40))) -> 273420 | AH40: =IF(AF40="TEC Rejected","",IF(AF40="","",AF40*IF(AE40="",$E40,AE40))) | AI40: 28 | AJ40: 14940 | AL40: =IF(AJ40="TEC Rejected","",IF(AJ40="","",AJ40*IF(AI40="",$E40,AI40))) -> 418320 | AP40: =IF(AN40="TEC Rejected","",IF(AN40="","",AN40*IF(AM40="",$E40,AM40))) | AT40: =IF(AR40="TEC Rejected","",IF(AR40="","",AR40*IF(AQ40="",$E40,AQ40))) | AX40: =IF(AV40="TEC Rejected","",IF(AV40="","",AV40*IF(AU40="",$E40,AU40))) | BB40: =IF(AZ40="TEC Rejected","",IF(AZ40="","",AZ40*IF(AY40="",$E40,AY40))) | BF40: =IF(BD40="TEC Rejected","",IF(BD40="","",BD40*IF(BC40="",$E40,BC40)))
...

Sheet CST-Final
A1: =CONCATENATE("Price Comparision Statement Against Indent ",Form!D2) -> Price Comparision Statement Against Indent abcd001 | AZ1: =IF(MAX(A4:A430)=MAX(B4:B430),"",VLOOKUP(1,A:BB,51,FALSE)) | BP1: =IF(VLOOKUP(1,A:BY,40,FALSE)=0,"","LPP/APPROVED:") -> LPP/APPROVED: | BT1: Annex-i
A2: RFQ DETAILS | G2: ='CST-Calculation'!G2 -> Aviation Equipment | K2: ='CST-Calculation'!K2 -> Avitronic Ltd, Russia | O2: ='CST-Calculation'!O2 -> GIS | S2: ='CST-Calculation'!S2 -> INDO AVIA SERVICES LTD | W2: ='CST-Calculation'!W2 -> AEC (AEC) | AA2: ='CST-Calculation'!AA2 -> ADRYS Technologies (ADRYS) | AE2: ='CST-Calculation'!AE2 -> AVIAZAPCHAST (AZP) | AI2: ='CST-Calculation'!AI2 -> Eurasia Special Technologies (EST) | AM2: ='CST-Calculation'!AM2 -> NASC (NASC) | AQ2: ='CST-Calculation'!AQ2 -> ROE (ROE) | AU2: ='CST-Calculation'!AU2 -> VEKS-M | AY2: L1 DETAILS | BF2: ESTIMATION DETAILS (LPP) if any | BK2: APPROVED ESTIMATION DETAILS | BP2: =IF(VLOOKUP(1,A:BY,40,FALSE)=0,"PRICE ANALYSIS","ORIGINAL PRICE ANALYSIS") -> ORIGINAL PRICE ANALYSIS | BU2: PRICE ANALYSIS AFTER PNC
H3: ='CST-Calculation'!H3 -> Avi. Equip. | L3: ='CST-Calculation'!L3 -> Avitronic | P3: ='CST-Calculation'!P3 -> GIS | T3: ='CST-Calculation'!T3 -> IASL | X3: ='CST-Calculation'!X3 -> AEC | AB3: ='CST-Calculation'!AB3 -> ADRYS | AF3: ='CST-Calculation'!AF3 -> AZP | AJ3: ='CST-Calculation'!AJ3 -> EST | AN3: ='CST-Calculation'!AN3 -> NASC | AR3: ='CST-Calculation'!AR3 -> ROE | AV3: ='CST-Calculation'!AV3 -> VEKS-M
A4: Sl No | B4: IND. Sl. No. | C4: PART NO | D4: DESCRIPTION | E4: QTY | F4: Revised QTY | G4: QTY | H4: Unit Price (USD) | I4: Level Unit Cost (INR.) | J4: Total Price (CTC) (INR) | K4: QTY | L4: Unit Price (USD) | M4: Level Unit Cost (INR.) | N4: Total Price (CTC) (INR) | O4: QTY | P4: Unit Price (USD) | Q4: Level Unit Cost (INR.) | R4: Total Price (CTC) (INR) | S4: QTY | T4: Unit Price (USD) | U4: Level Unit Cost (INR.) | V4: Total Price (CTC) (INR) | W4: QTY | X4: Unit Price (USD) | Y4: Level Unit Cost (INR.) | Z4: Total Price (CTC) (INR) | AA4: QTY | AB4: Unit Price (INR) | AC4: Level Unit Cost (INR.) | AD4: Total Price (CTC) (INR) | AE4: QTY | AF4: Unit Price (USD) | AG4: Level Unit Cost (INR.) | AH4: Total Price (CTC) (INR) | AI4: QTY | AJ4: Unit Price (INR) | AK4: Level Unit Cost (INR.) | AL4: Total Price (CTC) (INR) | AM4: QTY | AN4: Unit Price (USD) | AO4: Level Unit Cost (INR.) | AP4: Total Price (CTC) (INR) | AQ4: QTY | AR4: Unit Price (USD) | AS4: Level Unit Cost (INR.) | AT4: Total Price (CTC) (INR) | AU4: QTY | AV4: Unit Price (USD) | AW4: Level Unit Cost (INR.) | AX4: Total Price (CTC) (INR) | AY4: L1 AGENCY | AZ4: OFFER TYPE | BA4: MOQ Status in Excess to Indent Qty | BB4: L1 Unit PRICE (USD/INR) | BC4: L1 Total PRICE (USD/INR) | BD4: Level L1 Unit PRICE (INR) | BE4: Level L1 Total PRICE (INR) | BF4: REF SA Price(USD) | BG4: REF SA | BH4: REF SA Date | BI4: EST Unit Price (USD/INR) @ 2024 level | BJ4: Levelled EST Unit Price (INR) @ 2024 level | BK4: REF SA Price | BL4: REF SA | BM4: REF SA Date | BN4: EST Unit Price (USD) @ 2024 level | BO4: Levelled EST Unit Price (INR) @ 2024 level | BP4: L1 TOTAL Price (USD) @ 2024 level | BQ4: EST.TOTAL Price (USD) @ 2024 level | BR4: Levelled L1 TOTAL Price (INR) @ 2024 level | BS4: Levelled EST.TOTAL Apprvd Estimated Price (INR) @ 2024 level | BT4: Offered Price w.r.t Est Price (in%) | BU4: L1 UNIT Price (USD/RS) @ 2024 level | BV4: L1 TOTAL Price (USD/Rs) @ 2024 level | BW4: Levelled L1 UNIT Price (Rs) @ 2024 level | BX4: Levelled L1 TOTAL Price (Rs) @ 2024 level | BY4: Offered Price w.r.t Est Price (in%) | BZ4: Levelled EST.TOTAL LPP Price (INR) @ 2024 level | CA4: After PNC Deleted | CB4: Reason for deletion | CC4: Price Change | CD4: Project | CE4: Remarks(Do not Delete) | CF4: Techncal Estimate File no | CG4: File No. | CH4: MPR No. | CI4: MPR Date
